Workbook
Name RampaStress: 'Stress Test & Sensibilidad'!$E$19
Name FactorADR: 'Stress Test & Sensibilidad'!$E$17
Name FactorCuota: 'Stress Test & Sensibilidad'!$E$24
Name ChurnEsc: Supuestos!$E$19
Name TasaISR: 'Valuación Contrato Bravante'!$B$10
Name Tramo3: Supuestos!$B$11
Name RampaEsc: Supuestos!$E$17
Name DeltaCobranza: 'Stress Test & Sensibilidad'!$E$29
Name Tramo2: Supuestos!$B$10
Name AnioBase: Supuestos!$B$7
Name Escenario: Supuestos!$B$13
Name CrecimientoADR: Supuestos!$B$25
Name FactorCosto: 'Stress Test & Sensibilidad'!$E$33
Name PctConvenio: Supuestos!$B$2
Name FactorOcc: 'Stress Test & Sensibilidad'!$E$18
Name FilaVentaEsc: Supuestos!$E$15
Name ChurnNeto: Supuestos!$B$24
Name PctCapexRep: 'Valuación Contrato Bravante'!$B$30
Name EscenarioStress: 'Stress Test & Sensibilidad'!$B$3
Name CapexStress: 'Stress Test & Sensibilidad'!$E$28
Name CACporLlave: Supuestos!$B$26
Name CuotaSeg2: Supuestos!$B$5
Name Tramo1: Supuestos!$B$9
Name VidaUtilDep: 'Valuación Contrato Bravante'!$B$29
Name EV_Parametrico: 'Stress Test & Sensibilidad'!$B$125
Name FactorNomina: 'Stress Test & Sensibilidad'!$E$27
Name DiasCapTrab: 'Valuación Contrato Bravante'!$B$31
Name LagStress: 'Stress Test & Sensibilidad'!$E$22
Name ConvenioStress: 'Stress Test & Sensibilidad'!$E$25
Name MultSalida: 'Valuación Contrato Bravante'!$B$28
Name ModoStress: 'Stress Test & Sensibilidad'!$B$5
Name FactorLlaves: 'Stress Test & Sensibilidad'!$E$32
Name TopeLlaves: Supuestos!$B$27
Name InflacionStress: 'Stress Test & Sensibilidad'!$E$26
Name ChurnStress: 'Stress Test & Sensibilidad'!$E$20
Name UsoPropEsc: Supuestos!$E$18
Name WACCStress: 'Stress Test & Sensibilidad'!$E$30
Name WACC: 'Valuación Contrato Bravante'!$B$18
Name RepartoStress: 'Stress Test & Sensibilidad'!$E$23
Name ChurnBruto: Supuestos!$B$21
Name ReposicionStress: 'Stress Test & Sensibilidad'!$E$21
Name LagReposicion: Supuestos!$B$23
Name InflacionAnual: Supuestos!$B$6
Name TasaReposicion: Supuestos!$B$22
Name PctReparto: Supuestos!$B$3
Name CrecMercadoEsc: Supuestos!$E$16
Name PlazoContrato: 'Valuación Contrato Bravante'!$B$22
Name CuotaSeg1: Supuestos!$B$4
Name InflacionEsc: Supuestos!$E$20

Sheet Supuestos
A1: SUPUESTOS DEL MODELO — BRAVANTE
A2: % Convenio Limpieza & Mantenimiento (s/ venta) | B2: 0.0833
A3: % Reparto base a Propietarios (s/ venta) | B3: 0.75
A4: Cuota fija por unidad — Segmento No. 1 | B4: 1785
A5: Cuota fija por unidad — Segmento No. 2 | B5: 2870.45
A6: Inflación anual (gastos fijos) | B6: =InflacionEsc -> 0.045
A7: Año base | B7: 2025
A9: Nómina — tramo 1 (hasta 40 unidades): multiplicador | B9: 1
A10: Nómina — tramo 2 (41 a 80 unidades): multiplicador | B10: 1.6
A11: Nómina — tramo 3 (81+ unidades): multiplicador | B11: 2.2
A13: ESCENARIOS | B13: 2 | C13: (1 = Bear, 2 = Base, 3 = Bull)
A14: Driver | B14: Bear | C14: Base | D14: Bull | E14: Activo
A15: Fila de venta en archivo de mercado | B15: 9 | C15: 8 | D15: 7 | E15: {=INDEX(B15:D15,1,Escenario)} -> 8
A16: Crecimiento anual mercado (ADR) | B16: 0.02 | C16: 0.04 | D16: 0.06 | E16: {=INDEX(B16:D16,1,Escenario)} -> 0.04
A17: Meses de rampa | B17: 24 | C17: 18 | D17: 12 | E17: {=INDEX(B17:D17,1,Escenario)} -> 18
A18: Uso de propietario (% noches) | B18: 0.08 | C18: 0.05 | D18: 0.03 | E18: {=INDEX(B18:D18,1,Escenario)} -> 0.05
A19: Churn neto anual | B19: 0.1 | C19: 0.06 | D19: 0.03 | E19: {=INDEX(B19:D19,1,Escenario)} -> 0.06
A20: Inflación anual (gastos fijos) | B20: 0.06 | C20: 0.045 | D20: 0.035 | E20: {=INDEX(B20:D20,1,Escenario)} -> 0.045
A21: Churn bruto anual (salidas de propietarios) | B21: 0.06
A22: Tasa de reposición de llaves | B22: 0.6 | C22: El 60% es una base provisional; el canal de reventa y refirma está confirmado como real pero la tasa aún no se ha medido.
A23: Lag de reposición (meses de vacancia) | B23: 3
A24: Churn neto efectivo (calculado) | B24: =B21*(1-B22) -> 0.024
A25: Crecimiento de ADR largo plazo | B25: {=INDEX(B16:D16,1,$B$13)} -> 0.04
A26: CAC por llave repuesta | B26: ='Paso 5 Resumen Desglose de Inve'!$D$68/89 -> 8251.4607
A27: Tope físico de llaves (edificio) | B27: 117
A28: Churn bruto | B28: 0.1 | C28: 0.06 | D28: 0.03 | E28: =INDEX(B28:D28,1,$B$13) -> 0.06
A29: Tasa de reposición | B29: 0.3 | C29: 0.6 | D29: 0.85 | E29: =INDEX(B29:D29,1,$B$13) -> 0.6
A30: Lag de reposición | B30: 5 | C30: 3 | D30: 2 | E30: =INDEX(B30:D30,1,$B$13) -> 3

Sheet Profit & Loss
A2: Fechas | D2: ="Q"&ROUNDUP(MONTH(D$3)/3, 0)&" "&YEAR(D$3) -> Q1 2025 | G2: ="Q"&ROUNDUP(MONTH(G$3)/3, 0)&" "&YEAR(G$3) -> Q2 2025 | J2: ="Q"&ROUNDUP(MONTH(J$3)/3, 0)&" "&YEAR(J$3) -> Q3 2025 | M2: ="Q"&ROUNDUP(MONTH(M$3)/3, 0)&" "&YEAR(M$3) -> Q4 2025
D3: 45658 | E3: =EDATE(D3,1) -> 45689 | F3: =EDATE(E3,1) -> 45717 | G3: =EDATE(F3,1) -> 45748 | H3: =EDATE(G3,1) -> 45778 | I3: =EDATE(H3,1) -> 45809 | J3: =EDATE(I3,1) -> 45839 | K3: =EDATE(J3,1) -> 45870 | L3: =EDATE(K3,1) -> 45901 | ... BK3: =EDATE(BJ3,1) -> 47453 | BL3: TOTAL | BM3: PROMEDIO
A4: Factor Stress Venta | D4: =IF(ModoStress="ON", FactorADR*FactorOcc*FactorLlaves, 1) -> 1 | E4: =IF(ModoStress="ON", FactorADR*FactorOcc*FactorLlaves, 1) -> 1 | F4: =IF(ModoStress="ON", FactorADR*FactorOcc*FactorLlaves, 1) -> 1 | G4: =IF(ModoStress="ON", FactorADR*FactorOcc*FactorLlaves, 1) -> 1 | H4: =IF(ModoStress="ON", FactorADR*FactorOcc*FactorLlaves, 1) -> 1 | I4: =IF(ModoStress="ON", FactorADR*FactorOcc*FactorLlaves, 1) -> 1 | J4: =IF(ModoStress="ON", FactorADR*FactorOcc*FactorLlaves, 1) -> 1 | K4: =IF(ModoStress="ON", FactorADR*FactorOcc*FactorLlaves, 1) -> 1 | ... BK4: =IF(ModoStress="ON", FactorADR*FactorOcc*FactorLlaves, 1) -> 1
A5: Factor Stress Costo | D5: =IF(ModoStress="ON", FactorCosto, 1) -> 1 | E5: =IF(ModoStress="ON", FactorCosto, 1) -> 1 | F5: =IF(ModoStress="ON", FactorCosto, 1) -> 1 | G5: =IF(ModoStress="ON", FactorCosto, 1) -> 1 | H5: =IF(ModoStress="ON", FactorCosto, 1) -> 1 | I5: =IF(ModoStress="ON", FactorCosto, 1) -> 1 | J5: =IF(ModoStress="ON", FactorCosto, 1) -> 1 | K5: =IF(ModoStress="ON", FactorCosto, 1) -> 1 | ... BK5: =IF(ModoStress="ON", FactorCosto, 1) -> 1
A6: Factor Reposición Llaves | D6: =IF(ModoStress="ON", ((1-ChurnNeto)/(1-ChurnBruto))^(YEAR(D$3)-AnioBase), 1) -> 1 | E6: =IF(ModoStress="ON", ((1-ChurnNeto)/(1-ChurnBruto))^(YEAR(E$3)-AnioBase), 1) -> 1 | F6: =IF(ModoStress="ON", ((1-ChurnNeto)/(1-ChurnBruto))^(YEAR(F$3)-AnioBase), 1) -> 1 | G6: =IF(ModoStress="ON", ((1-ChurnNeto)/(1-ChurnBruto))^(YEAR(G$3)-AnioBase), 1) -> 1 | H6: =IF(ModoStress="ON", ((1-ChurnNeto)/(1-ChurnBruto))^(YEAR(H$3)-AnioBase), 1) -> 1 | I6: =IF(ModoStress="ON", ((1-ChurnNeto)/(1-ChurnBruto))^(YEAR(I$3)-AnioBase), 1) -> 1 | J6: =IF(ModoStress="ON", ((1-ChurnNeto)/(1-ChurnBruto))^(YEAR(J$3)-AnioBase), 1) -> 1 | K6: =IF(ModoStress="ON", ((1-ChurnNeto)/(1-ChurnBruto))^(YEAR(K$3)-AnioBase), 1) -> 1 | ... BK6: =IF(ModoStress="ON", ((1-ChurnNeto)/(1-ChurnBruto))^(YEAR(BK$3)-AnioBase), 1) -> 1
A7: Venta Total (Despues de Comisiones OTAs + Pasarelas de Pago, IVA e Impuestos) | D7: =IFERROR(D8+D13,"Revise Error") -> 1000411.7 | E7: =IFERROR(E8+E13,"Revise Error") -> 1047043.8 | F7: =IFERROR(F8+F13,"Revise Error") -> 1066178.5 | G7: =IFERROR(G8+G13,"Revise Error") -> 1013043.5 | H7: =IFERROR(H8+H13,"Revise Error") -> 1037076 | I7: =IFERROR(I8+I13,"Revise Error") -> 1035263.9 | J7: =IFERROR(J8+J13,"Revise Error") -> 1090332 | K7: =IFERROR(K8+K13,"Revise Error") -> 1084090.5 | ... BK7: =IFERROR(BK8+BK13,"Revise Error") -> 907885.76 | BL7: =SUM(D7:BK7) -> 58754723 | BM7: =AVERAGE(D7:BK7) -> 979245.38
B8: ({UO} | AT-AMP-02) - Analisis de Mercado [No. 1 - KIVA] | D8: =IFERROR(__xludf.DUMMYFUNCTION("IFERROR(IMPORTRANGE(""https://docs.google.com/spreadsheets/d/10OcXjkVvXdQ20Dikey2wLwZD9Qs97Ke_ckzbHR2FA6E/edit?usp=sharing"", ""P1!E"" & FilaVentaEsc & "":BL"" & FilaVentaEsc))"),584744.4227656598) -> 584744.42 | E8: =IFERROR(__xludf.DUMMYFUNCTION("""COMPUTED_VALUE"""),632467.9730076719) -> 632467.97 | F8: =IFERROR(__xludf.DUMMYFUNCTION("""COMPUTED_VALUE"""),562671.2386455302) -> 562671.24 | G8: =IFERROR(__xludf.DUMMYFUNCTION("""COMPUTED_VALUE"""),606607.4703135559) -> 606607.47 | H8: =IFERROR(__xludf.DUMMYFUNCTION("""COMPUTED_VALUE"""),621981.6067745518) -> 621981.61 | I8: =IFERROR(__xludf.DUMMYFUNCTION("""COMPUTED_VALUE"""),622790.5486921028) -> 622790.55 | J8: =IFERROR(__xludf.DUMMYFUNCTION("""COMPUTED_VALUE"""),620667.8985979322) -> 620667.9 | K8: =IFERROR(__xludf.DUMMYFUNCTION("""COMPUTED_VALUE"""),599013.773384289) -> 599013.77 | L8: =IFERROR(__xludf.DUMMYFUNCTION("""COMPUTED_VALUE"""),582469.4162353423) -> 582469.42 | M8: =IFERROR(__xludf.DUMMYFUNCTION("""COMPUTED_VALUE"""),564299.5817159889) -> 564299.58 | N8: =IFERROR(__xludf.DUMMYFUNCTION("""COMPUTED_VALUE"""),629444.6701355868) -> 629444.67 | O8: =IFERROR(__xludf.DUMMYFUNCTION("""COMPUTED_VALUE"""),594748.7661271) -> 594748.77 | P8: =IFERROR(__xludf.DUMMYFUNCTION("""COMPUTED_VALUE"""),571646.1476957088) -> 571646.15 | Q8: =IFERROR(__xludf.DUMMYFUNCTION("""COMPUTED_VALUE"""),618300.6904123) -> 618300.69 | R8: =IFERROR(__xludf.DUMMYFUNCTION("""COMPUTED_VALUE"""),550067.4028998703) -> 550067.4 | S8: =IFERROR(__xludf.DUMMYFUNCTION("""COMPUTED_VALUE"""),593019.4629785322) -> 593019.46 | T8: =IFERROR(__xludf.DUMMYFUNCTION("""COMPUTED_VALUE"""),608049.2187828018) -> 608049.22 | U8: =IFERROR(__xludf.DUMMYFUNCTION("""COMPUTED_VALUE"""),608840.0404013997) -> 608840.04 | V8: =IFERROR(__xludf.DUMMYFUNCTION("""COMPUTED_VALUE"""),606764.9376693384) -> 606764.94 | W8: =IFERROR(__xludf.DUMMYFUNCTION("""COMPUTED_VALUE"""),585595.864860481) -> 585595.86 | X8: =IFERROR(__xludf.DUMMYFUNCTION("""COMPUTED_VALUE"""),569422.1013116706) -> 569422.1 | Y8: =IFERROR(__xludf.DUMMYFUNCTION("""COMPUTED_VALUE"""),551659.2710855508) -> 551659.27 | Z8: =IFERROR(__xludf.DUMMYFUNCTION("""COMPUTED_VALUE"""),615345.1095245496) -> 615345.11 | AA8: =IFERROR(__xludf.DUMMYFUNCTION("""COMPUTED_VALUE"""),581426.3937658529) -> 581426.39 | AB8: =IFERROR(__xludf.DUMMYFUNCTION("""COMPUTED_VALUE"""),558841.2739873251) -> 558841.27 | AC8: =IFERROR(__xludf.DUMMYFUNCTION("""COMPUTED_VALUE"""),604450.7549470644) -> 604450.75 | AD8: =IFERROR(__xludf.DUMMYFUNCTION("""COMPUTED_VALUE"""),537745.8930749132) -> 537745.89 | AE8: =IFERROR(__xludf.DUMMYFUNCTION("""COMPUTED_VALUE"""),579735.8270078131) -> 579735.83 | AF8: =IFERROR(__xludf.DUMMYFUNCTION("""COMPUTED_VALUE"""),594428.916282067) -> 594428.92 | AG8: =IFERROR(__xludf.DUMMYFUNCTION("""COMPUTED_VALUE"""),595202.0234964084) -> 595202.02 | AH8: =IFERROR(__xludf.DUMMYFUNCTION("""COMPUTED_VALUE"""),593173.4030655453) -> 593173.4 | AI8: =IFERROR(__xludf.DUMMYFUNCTION("""COMPUTED_VALUE"""),572478.517487606) -> 572478.52 | AJ8: =IFERROR(__xludf.DUMMYFUNCTION("""COMPUTED_VALUE"""),556667.0462422892) -> 556667.05 | AK8: =IFERROR(__xludf.DUMMYFUNCTION("""COMPUTED_VALUE"""),539302.1034132345) -> 539302.1 | AL8: =IFERROR(__xludf.DUMMYFUNCTION("""COMPUTED_VALUE"""),601561.3790711998) -> 601561.38 | AM8: =IFERROR(__xludf.DUMMYFUNCTION("""COMPUTED_VALUE"""),568402.4425454979) -> 568402.44 | AN8: =IFERROR(__xludf.DUMMYFUNCTION("""COMPUTED_VALUE"""),546323.229450009) -> 546323.23 | AO8: =IFERROR(__xludf.DUMMYFUNCTION("""COMPUTED_VALUE"""),612015.0243946877) -> 612015.02 | AP8: =IFERROR(__xludf.DUMMYFUNCTION("""COMPUTED_VALUE"""),525611.2750244924) -> 525611.28 | AQ8: =IFERROR(__xludf.DUMMYFUNCTION("""COMPUTED_VALUE"""),566653.6762717877) -> 566653.68 | AR8: =IFERROR(__xludf.DUMMYFUNCTION("""COMPUTED_VALUE"""),581015.2055497313) -> 581015.21 | AS8: =IFERROR(__xludf.DUMMYFUNCTION("""COMPUTED_VALUE"""),581770.8670506254) -> 581770.87 | AT8: =IFERROR(__xludf.DUMMYFUNCTION("""COMPUTED_VALUE"""),579788.0238807601) -> 579788.02 | AU8: =IFERROR(__xludf.DUMMYFUNCTION("""COMPUTED_VALUE"""),559560.133095937) -> 559560.13 | AV8: =IFERROR(__xludf.DUMMYFUNCTION("""COMPUTED_VALUE"""),544105.4589305196) -> 544105.46 | AW8: =IFERROR(__xludf.DUMMYFUNCTION("""COMPUTED_VALUE"""),527132.3683711179) -> 527132.37 | AX8: =IFERROR(__xludf.DUMMYFUNCTION("""COMPUTED_VALUE"""),587986.719249676) -> 587986.72 | AY8: =IFERROR(__xludf.DUMMYFUNCTION("""COMPUTED_VALUE"""),555576.0376802264) -> 555576.04 | AZ8: =IFERROR(__xludf.DUMMYFUNCTION("""COMPUTED_VALUE"""),533995.0577116064) -> 533995.06 | BA8: =IFERROR(__xludf.DUMMYFUNCTION("""COMPUTED_VALUE"""),577576.7302740464) -> 577576.73 | BB8: =IFERROR(__xludf.DUMMYFUNCTION("""COMPUTED_VALUE"""),513837.58246394387) -> 513837.58 | BC8: =IFERROR(__xludf.DUMMYFUNCTION("""COMPUTED_VALUE"""),553960.6339232996) -> 553960.63 | BD8: =IFERROR(__xludf.DUMMYFUNCTION("""COMPUTED_VALUE"""),568000.4649454176) -> 568000.46 | BE8: =IFERROR(__xludf.DUMMYFUNCTION("""COMPUTED_VALUE"""),568739.1996286915) -> 568739.2 | BF8: =IFERROR(__xludf.DUMMYFUNCTION("""COMPUTED_VALUE"""),566800.772145831) -> 566800.77 | BG8: =IFERROR(__xludf.DUMMYFUNCTION("""COMPUTED_VALUE"""),547025.986114588) -> 547025.99 | BH8: =IFERROR(__xludf.DUMMYFUNCTION("""COMPUTED_VALUE"""),531917.4966504759) -> 531917.5 | BI8: =IFERROR(__xludf.DUMMYFUNCTION("""COMPUTED_VALUE"""),515324.6033196048) -> 515324.6 | BJ8: =IFERROR(__xludf.DUMMYFUNCTION("""COMPUTED_VALUE"""),574815.8167384833) -> 574815.82 | BK8: =IFERROR(__xludf.DUMMYFUNCTION("""COMPUTED_VALUE"""),543131.1344361893) -> 543131.13 | BL8: =SUM(D8:BK8) -> 34546697 | BM8: =AVERAGE(D8:BK8) -> 575778.28
C9: Property Count | D9: =IFERROR(__xludf.DUMMYFUNCTION("IF(IMPORTRANGE(""https://docs.google.com/spreadsheets/d/10OcXjkVvXdQ20Dikey2wLwZD9Qs97Ke_ckzbHR2FA6E/edit?usp=sharing"", ""P1!$B$11"")=1, IFERROR(INDEX(IMPORTRANGE(""https://docs.google.com/spreadsheets/d/10OcXjkVvXdQ20Dikey2wLwZD9Qs97Ke_ckzbHR2FA6E/"&"edit?usp=sharing"", ""P1!$E$6:$BL$6""), MATCH(D3, IMPORTRANGE(""https://docs.google.com/spreadsheets/d/10OcXjkVvXdQ20Dikey2wLwZD9Qs97Ke_ckzbHR2FA6E/edit?usp=sharing"", ""P1!$E$4:$BL$4""), 0)), ""Unknown""), IF(IMPORTRANGE(""https://docs.google."&"com/spreadsheets/d/10OcXjkVvXdQ20Dikey2wLwZD9Qs97Ke_ckzbHR2FA6E/edit?usp=sharing"", ""P1!$B$11"")=2, 0, ""Unknown""))"),24.7) -> 24.7 | E9: =IFERROR(__xludf.DUMMYFUNCTION("IF(IMPORTRANGE(""https://docs.google.com/spreadsheets/d/10OcXjkVvXdQ20Dikey2wLwZD9Qs97Ke_ckzbHR2FA6E/edit?usp=sharing"", ""P1!$B$11"")=1, IFERROR(INDEX(IMPORTRANGE(""https://docs.google.com/spreadsheets/d/10OcXjkVvXdQ20Dikey2wLwZD9Qs97Ke_ckzbHR2FA6E/"&"edit?usp=sharing"", ""P1!$E$6:$BL$6""), MATCH(E3, IMPORTRANGE(""https://docs.google.com/spreadsheets/d/10OcXjkVvXdQ20Dikey2wLwZD9Qs97Ke_ckzbHR2FA6E/edit?usp=sharing"", ""P1!$E$4:$BL$4""), 0)), ""Unknown""), IF(IMPORTRANGE(""https://docs.google."&"com/spreadsheets/d/10OcXjkVvXdQ20Dikey2wLwZD9Qs97Ke_ckzbHR2FA6E/edit?usp=sharing"", ""P1!$B$11"")=2, 0, ""Unknown""))"),24.5705377406331) -> 24.570538 | F9: =IFERROR(__xludf.DUMMYFUNCTION("IF(IMPORTRANGE(""https://docs.google.com/spreadsheets/d/10OcXjkVvXdQ20Dikey2wLwZD9Qs97Ke_ckzbHR2FA6E/edit?usp=sharing"", ""P1!$B$11"")=1, IFERROR(INDEX(IMPORTRANGE(""https://docs.google.com/spreadsheets/d/10OcXjkVvXdQ20Dikey2wLwZD9Qs97Ke_ckzbHR2FA6E/"&"edit?usp=sharing"", ""P1!$E$6:$BL$6""), MATCH(F3, IMPORTRANGE(""https://docs.google.com/spreadsheets/d/10OcXjkVvXdQ20Dikey2wLwZD9Qs97Ke_ckzbHR2FA6E/edit?usp=sharing"", ""P1!$E$4:$BL$4""), 0)), ""Unknown""), IF(IMPORTRANGE(""https://docs.google."&"com/spreadsheets/d/10OcXjkVvXdQ20Dikey2wLwZD9Qs97Ke_ckzbHR2FA6E/edit?usp=sharing"", ""P1!$B$11"")=2, 0, ""Unknown""))"),24.45418742411264) -> 24.454187 | G9: =IFERROR(__xludf.DUMMYFUNCTION("IF(IMPORTRANGE(""https://docs.google.com/spreadsheets/d/10OcXjkVvXdQ20Dikey2wLwZD9Qs97Ke_ckzbHR2FA6E/edit?usp=sharing"", ""P1!$B$11"")=1, IFERROR(INDEX(IMPORTRANGE(""https://docs.google.com/spreadsheets/d/10OcXjkVvXdQ20Dikey2wLwZD9Qs97Ke_ckzbHR2FA6E/"&"edit?usp=sharing"", ""P1!$E$6:$BL$6""), MATCH(G3, IMPORTRANGE(""https://docs.google.com/spreadsheets/d/10OcXjkVvXdQ20Dikey2wLwZD9Qs97Ke_ckzbHR2FA6E/edit?usp=sharing"", ""P1!$E$4:$BL$4""), 0)), ""Unknown""), IF(IMPORTRANGE(""https://docs.google."&"com/spreadsheets/d/10OcXjkVvXdQ20Dikey2wLwZD9Qs97Ke_ckzbHR2FA6E/edit?usp=sharing"", ""P1!$B$11"")=2, 0, ""Unknown""))"),24.32601356359008) -> 24.326014 | H9: =IFERROR(__xludf.DUMMYFUNCTION("IF(IMPORTRANGE(""https://docs.google.com/spreadsheets/d/10OcXjkVvXdQ20Dikey2wLwZD9Qs97Ke_ckzbHR2FA6E/edit?usp=sharing"", ""P1!$B$11"")=1, IFERROR(INDEX(IMPORTRANGE(""https://docs.google.com/spreadsheets/d/10OcXjkVvXdQ20Dikey2wLwZD9Qs97Ke_ckzbHR2FA6E/"&"edit?usp=sharing"", ""P1!$E$6:$BL$6""), MATCH(H3, IMPORTRANGE(""https://docs.google.com/spreadsheets/d/10OcXjkVvXdQ20Dikey2wLwZD9Qs97Ke_ckzbHR2FA6E/edit?usp=sharing"", ""P1!$E$4:$BL$4""), 0)), ""Unknown""), IF(IMPORTRANGE(""https://docs.google."&"com/spreadsheets/d/10OcXjkVvXdQ20Dikey2wLwZD9Qs97Ke_ckzbHR2FA6E/edit?usp=sharing"", ""P1!$B$11"")=2, 0, ""Unknown""))"),24.20261403129571) -> 24.202614 | I9: =IFERROR(__xludf.DUMMYFUNCTION("IF(IMPORTRANGE(""https://docs.google.com/spreadsheets/d/10OcXjkVvXdQ20Dikey2wLwZD9Qs97Ke_ckzbHR2FA6E/edit?usp=sharing"", ""P1!$B$11"")=1, IFERROR(INDEX(IMPORTRANGE(""https://docs.google.com/spreadsheets/d/10OcXjkVvXdQ20Dikey2wLwZD9Qs97Ke_ckzbHR2FA6E/"&"edit?usp=sharing"", ""P1!$E$6:$BL$6""), MATCH(I3, IMPORTRANGE(""https://docs.google.com/spreadsheets/d/10OcXjkVvXdQ20Dikey2wLwZD9Qs97Ke_ckzbHR2FA6E/edit?usp=sharing"", ""P1!$E$4:$BL$4""), 0)), ""Unknown""), IF(IMPORTRANGE(""https://docs.google."&"com/spreadsheets/d/10OcXjkVvXdQ20Dikey2wLwZD9Qs97Ke_ckzbHR2FA6E/edit?usp=sharing"", ""P1!$B$11"")=2, 0, ""Unknown""))"),24.07575876428856) -> 24.075759 | J9: =IFERROR(__xludf.DUMMYFUNCTION("IF(IMPORTRANGE(""https://docs.google.com/spreadsheets/d/10OcXjkVvXdQ20Dikey2wLwZD9Qs97Ke_ckzbHR2FA6E/edit?usp=sharing"", ""P1!$B$11"")=1, IFERROR(INDEX(IMPORTRANGE(""https://docs.google.com/spreadsheets/d/10OcXjkVvXdQ20Dikey2wLwZD9Qs97Ke_ckzbHR2FA6E/"&"edit?usp=sharing"", ""P1!$E$6:$BL$6""), MATCH(J3, IMPORTRANGE(""https://docs.google.com/spreadsheets/d/10OcXjkVvXdQ20Dikey2wLwZD9Qs97Ke_ckzbHR2FA6E/edit?usp=sharing"", ""P1!$E$4:$BL$4""), 0)), ""Unknown""), IF(IMPORTRANGE(""https://docs.google."&"com/spreadsheets/d/10OcXjkVvXdQ20Dikey2wLwZD9Qs97Ke_ckzbHR2FA6E/edit?usp=sharing"", ""P1!$B$11"")=2, 0, ""Unknown""))"),23.953628709424493) -> 23.953629 | K9: =IFERROR(__xludf.DUMMYFUNCTION("IF(IMPORTRANGE(""https://docs.google.com/spreadsheets/d/10OcXjkVvXdQ20Dikey2wLwZD9Qs97Ke_ckzbHR2FA6E/edit?usp=sharing"", ""P1!$B$11"")=1, IFERROR(INDEX(IMPORTRANGE(""https://docs.google.com/spreadsheets/d/10OcXjkVvXdQ20Dikey2wLwZD9Qs97Ke_ckzbHR2FA6E/"&"edit?usp=sharing"", ""P1!$E$6:$BL$6""), MATCH(K3, IMPORTRANGE(""https://docs.google.com/spreadsheets/d/10OcXjkVvXdQ20Dikey2wLwZD9Qs97Ke_ckzbHR2FA6E/edit?usp=sharing"", ""P1!$E$4:$BL$4""), 0)), ""Unknown""), IF(IMPORTRANGE(""https://docs.google."&"com/spreadsheets/d/10OcXjkVvXdQ20Dikey2wLwZD9Qs97Ke_ckzbHR2FA6E/edit?usp=sharing"", ""P1!$B$11"")=2, 0, ""Unknown""))"),23.8280784708513) -> 23.828078 | L9: =IFERROR(__xludf.DUMMYFUNCTION("IF(IMPORTRANGE(""https://docs.google.com/spreadsheets/d/10OcXjkVvXdQ20Dikey2wLwZD9Qs97Ke_ckzbHR2FA6E/edit?usp=sharing"", ""P1!$B$11"")=1, IFERROR(INDEX(IMPORTRANGE(""https://docs.google.com/spreadsheets/d/10OcXjkVvXdQ20Dikey2wLwZD9Qs97Ke_ckzbHR2FA6E/"&"edit?usp=sharing"", ""P1!$E$6:$BL$6""), MATCH(L3, IMPORTRANGE(""https://docs.google.com/spreadsheets/d/10OcXjkVvXdQ20Dikey2wLwZD9Qs97Ke_ckzbHR2FA6E/edit?usp=sharing"", ""P1!$E$4:$BL$4""), 0)), ""Unknown""), IF(IMPORTRANGE(""https://docs.google."&"com/spreadsheets/d/10OcXjkVvXdQ20Dikey2wLwZD9Qs97Ke_ckzbHR2FA6E/edit?usp=sharing"", ""P1!$B$11"")=2, 0, ""Unknown""))"),23.703186289668782) -> 23.703186 | M9: =IFERROR(__xludf.DUMMYFUNCTION("IF(IMPORTRANGE(""https://docs.google.com/spreadsheets/d/10OcXjkVvXdQ20Dikey2wLwZD9Qs97Ke_ckzbHR2FA6E/edit?usp=sharing"", ""P1!$B$11"")=1, IFERROR(INDEX(IMPORTRANGE(""https://docs.google.com/spreadsheets/d/10OcXjkVvXdQ20Dikey2wLwZD9Qs97Ke_ckzbHR2FA6E/"&"edit?usp=sharing"", ""P1!$E$6:$BL$6""), MATCH(M3, IMPORTRANGE(""https://docs.google.com/spreadsheets/d/10OcXjkVvXdQ20Dikey2wLwZD9Qs97Ke_ckzbHR2FA6E/edit?usp=sharing"", ""P1!$E$4:$BL$4""), 0)), ""Unknown""), IF(IMPORTRANGE(""https://docs.google."&"com/spreadsheets/d/10OcXjkVvXdQ20Dikey2wLwZD9Qs97Ke_ckzbHR2FA6E/edit?usp=sharing"", ""P1!$B$11"")=2, 0, ""Unknown""))"),23.582946197950285) -> 23.582946 | N9: =IFERROR(__xludf.DUMMYFUNCTION("IF(IMPORTRANGE(""https://docs.google.com/spreadsheets/d/10OcXjkVvXdQ20Dikey2wLwZD9Qs97Ke_ckzbHR2FA6E/edit?usp=sharing"", ""P1!$B$11"")=1, IFERROR(INDEX(IMPORTRANGE(""https://docs.google.com/spreadsheets/d/10OcXjkVvXdQ20Dikey2wLwZD9Qs97Ke_ckzbHR2FA6E/"&"edit?usp=sharing"", ""P1!$E$6:$BL$6""), MATCH(N3, IMPORTRANGE(""https://docs.google.com/spreadsheets/d/10OcXjkVvXdQ20Dikey2wLwZD9Qs97Ke_ckzbHR2FA6E/edit?usp=sharing"", ""P1!$E$4:$BL$4""), 0)), ""Unknown""), IF(IMPORTRANGE(""https://docs.google."&"com/spreadsheets/d/10OcXjkVvXdQ20Dikey2wLwZD9Qs97Ke_ckzbHR2FA6E/edit?usp=sharing"", ""P1!$B$11"")=2, 0, ""Unknown""))"),23.45933884988087) -> 23.459339 | O9: =IFERROR(__xludf.DUMMYFUNCTION("IF(IMPORTRANGE(""https://docs.google.com/spreadsheets/d/10OcXjkVvXdQ20Dikey2wLwZD9Qs97Ke_ckzbHR2FA6E/edit?usp=sharing"", ""P1!$B$11"")=1, IFERROR(INDEX(IMPORTRANGE(""https://docs.google.com/spreadsheets/d/10OcXjkVvXdQ20Dikey2wLwZD9Qs97Ke_ckzbHR2FA6E/"&"edit?usp=sharing"", ""P1!$E$6:$BL$6""), MATCH(O3, IMPORTRANGE(""https://docs.google.com/spreadsheets/d/10OcXjkVvXdQ20Dikey2wLwZD9Qs97Ke_ckzbHR2FA6E/edit?usp=sharing"", ""P1!$E$4:$BL$4""), 0)), ""Unknown""), IF(IMPORTRANGE(""https://docs.google."&"com/spreadsheets/d/10OcXjkVvXdQ20Dikey2wLwZD9Qs97Ke_ckzbHR2FA6E/edit?usp=sharing"", ""P1!$B$11"")=2, 0, ""Unknown""))"),23.34033573272634) -> 23.340336 | P9: =IFERROR(__xludf.DUMMYFUNCTION("IF(IMPORTRANGE(""https://docs.google.com/spreadsheets/d/10OcXjkVvXdQ20Dikey2wLwZD9Qs97Ke_ckzbHR2FA6E/edit?usp=sharing"", ""P1!$B$11"")=1, IFERROR(INDEX(IMPORTRANGE(""https://docs.google.com/spreadsheets/d/10OcXjkVvXdQ20Dikey2wLwZD9Qs97Ke_ckzbHR2FA6E/"&"edit?usp=sharing"", ""P1!$E$6:$BL$6""), MATCH(P3, IMPORTRANGE(""https://docs.google.com/spreadsheets/d/10OcXjkVvXdQ20Dikey2wLwZD9Qs97Ke_ckzbHR2FA6E/edit?usp=sharing"", ""P1!$E$4:$BL$4""), 0)), ""Unknown""), IF(IMPORTRANGE(""https://docs.google."&"com/spreadsheets/d/10OcXjkVvXdQ20Dikey2wLwZD9Qs97Ke_ckzbHR2FA6E/edit?usp=sharing"", ""P1!$B$11"")=2, 0, ""Unknown""))"),23.217999999999996) -> 23.218 | Q9: =IFERROR(__xludf.DUMMYFUNCTION("IF(IMPORTRANGE(""https://docs.google.com/spreadsheets/d/10OcXjkVvXdQ20Dikey2wLwZD9Qs97Ke_ckzbHR2FA6E/edit?usp=sharing"", ""P1!$B$11"")=1, IFERROR(INDEX(IMPORTRANGE(""https://docs.google.com/spreadsheets/d/10OcXjkVvXdQ20Dikey2wLwZD9Qs97Ke_ckzbHR2FA6E/"&"edit?usp=sharing"", ""P1!$E$6:$BL$6""), MATCH(Q3, IMPORTRANGE(""https://docs.google.com/spreadsheets/d/10OcXjkVvXdQ20Dikey2wLwZD9Qs97Ke_ckzbHR2FA6E/edit?usp=sharing"", ""P1!$E$4:$BL$4""), 0)), ""Unknown""), IF(IMPORTRANGE(""https://docs.google."&"com/spreadsheets/d/10OcXjkVvXdQ20Dikey2wLwZD9Qs97Ke_ckzbHR2FA6E/edit?usp=sharing"", ""P1!$B$11"")=2, 0, ""Unknown""))"),23.096305476195113) -> 23.096305 | R9: =IFERROR(__xludf.DUMMYFUNCTION("IF(IMPORTRANGE(""https://docs.google.com/spreadsheets/d/10OcXjkVvXdQ20Dikey2wLwZD9Qs97Ke_ckzbHR2FA6E/edit?usp=sharing"", ""P1!$B$11"")=1, IFERROR(INDEX(IMPORTRANGE(""https://docs.google.com/spreadsheets/d/10OcXjkVvXdQ20Dikey2wLwZD9Qs97Ke_ckzbHR2FA6E/"&"edit?usp=sharing"", ""P1!$E$6:$BL$6""), MATCH(R3, IMPORTRANGE(""https://docs.google.com/spreadsheets/d/10OcXjkVvXdQ20Dikey2wLwZD9Qs97Ke_ckzbHR2FA6E/edit?usp=sharing"", ""P1!$E$4:$BL$4""), 0)), ""Unknown""), IF(IMPORTRANGE(""https://docs.google."&"com/spreadsheets/d/10OcXjkVvXdQ20Dikey2wLwZD9Qs97Ke_ckzbHR2FA6E/edit?usp=sharing"", ""P1!$B$11"")=2, 0, ""Unknown""))"),22.98693617866588) -> 22.986936 | S9: =IFERROR(__xludf.DUMMYFUNCTION("IF(IMPORTRANGE(""https://docs.google.com/spreadsheets/d/10OcXjkVvXdQ20Dikey2wLwZD9Qs97Ke_ckzbHR2FA6E/edit?usp=sharing"", ""P1!$B$11"")=1, IFERROR(INDEX(IMPORTRANGE(""https://docs.google.com/spreadsheets/d/10OcXjkVvXdQ20Dikey2wLwZD9Qs97Ke_ckzbHR2FA6E/"&"edit?usp=sharing"", ""P1!$E$6:$BL$6""), MATCH(S3, IMPORTRANGE(""https://docs.google.com/spreadsheets/d/10OcXjkVvXdQ20Dikey2wLwZD9Qs97Ke_ckzbHR2FA6E/edit?usp=sharing"", ""P1!$E$4:$BL$4""), 0)), ""Unknown""), IF(IMPORTRANGE(""https://docs.google."&"com/spreadsheets/d/10OcXjkVvXdQ20Dikey2wLwZD9Qs97Ke_ckzbHR2FA6E/edit?usp=sharing"", ""P1!$B$11"")=2, 0, ""Unknown""))"),22.866452749774673) -> 22.866453 | T9: =IFERROR(__xludf.DUMMYFUNCTION("IF(IMPORTRANGE(""https://docs.google.com/spreadsheets/d/10OcXjkVvXdQ20Dikey2wLwZD9Qs97Ke_ckzbHR2FA6E/edit?usp=sharing"", ""P1!$B$11"")=1, IFERROR(INDEX(IMPORTRANGE(""https://docs.google.com/spreadsheets/d/10OcXjkVvXdQ20Dikey2wLwZD9Qs97Ke_ckzbHR2FA6E/"&"edit?usp=sharing"", ""P1!$E$6:$BL$6""), MATCH(T3, IMPORTRANGE(""https://docs.google.com/spreadsheets/d/10OcXjkVvXdQ20Dikey2wLwZD9Qs97Ke_ckzbHR2FA6E/edit?usp=sharing"", ""P1!$E$4:$BL$4""), 0)), ""Unknown""), IF(IMPORTRANGE(""https://docs.google."&"com/spreadsheets/d/10OcXjkVvXdQ20Dikey2wLwZD9Qs97Ke_ckzbHR2FA6E/edit?usp=sharing"", ""P1!$B$11"")=2, 0, ""Unknown""))"),22.750457189417965) -> 22.750457 | U9: =IFERROR(__xludf.DUMMYFUNCTION("IF(IMPORTRANGE(""https://docs.google.com/spreadsheets/d/10OcXjkVvXdQ20Dikey2wLwZD9Qs97Ke_ckzbHR2FA6E/edit?usp=sharing"", ""P1!$B$11"")=1, IFERROR(INDEX(IMPORTRANGE(""https://docs.google.com/spreadsheets/d/10OcXjkVvXdQ20Dikey2wLwZD9Qs97Ke_ckzbHR2FA6E/"&"edit?usp=sharing"", ""P1!$E$6:$BL$6""), MATCH(U3, IMPORTRANGE(""https://docs.google.com/spreadsheets/d/10OcXjkVvXdQ20Dikey2wLwZD9Qs97Ke_ckzbHR2FA6E/edit?usp=sharing"", ""P1!$E$4:$BL$4""), 0)), ""Unknown""), IF(IMPORTRANGE(""https://docs.google."&"com/spreadsheets/d/10OcXjkVvXdQ20Dikey2wLwZD9Qs97Ke_ckzbHR2FA6E/edit?usp=sharing"", ""P1!$B$11"")=2, 0, ""Unknown""))"),22.631213238431247) -> 22.631213 | V9: =IFERROR(__xludf.DUMMYFUNCTION("IF(IMPORTRANGE(""https://docs.google.com/spreadsheets/d/10OcXjkVvXdQ20Dikey2wLwZD9Qs97Ke_ckzbHR2FA6E/edit?usp=sharing"", ""P1!$B$11"")=1, IFERROR(INDEX(IMPORTRANGE(""https://docs.google.com/spreadsheets/d/10OcXjkVvXdQ20Dikey2wLwZD9Qs97Ke_ckzbHR2FA6E/"&"edit?usp=sharing"", ""P1!$E$6:$BL$6""), MATCH(V3, IMPORTRANGE(""https://docs.google.com/spreadsheets/d/10OcXjkVvXdQ20Dikey2wLwZD9Qs97Ke_ckzbHR2FA6E/edit?usp=sharing"", ""P1!$E$4:$BL$4""), 0)), ""Unknown""), IF(IMPORTRANGE(""https://docs.google."&"com/spreadsheets/d/10OcXjkVvXdQ20Dikey2wLwZD9Qs97Ke_ckzbHR2FA6E/edit?usp=sharing"", ""P1!$B$11"")=2, 0, ""Unknown""))"),22.51641098685902) -> 22.516411 | W9: =IFERROR(__xludf.DUMMYFUNCTION("IF(IMPORTRANGE(""https://docs.google.com/spreadsheets/d/10OcXjkVvXdQ20Dikey2wLwZD9Qs97Ke_ckzbHR2FA6E/edit?usp=sharing"", ""P1!$B$11"")=1, IFERROR(INDEX(IMPORTRANGE(""https://docs.google.com/spreadsheets/d/10OcXjkVvXdQ20Dikey2wLwZD9Qs97Ke_ckzbHR2FA6E/"&"edit?usp=sharing"", ""P1!$E$6:$BL$6""), MATCH(W3, IMPORTRANGE(""https://docs.google.com/spreadsheets/d/10OcXjkVvXdQ20Dikey2wLwZD9Qs97Ke_ckzbHR2FA6E/edit?usp=sharing"", ""P1!$E$4:$BL$4""), 0)), ""Unknown""), IF(IMPORTRANGE(""https://docs.google."&"com/spreadsheets/d/10OcXjkVvXdQ20Dikey2wLwZD9Qs97Ke_ckzbHR2FA6E/edit?usp=sharing"", ""P1!$B$11"")=2, 0, ""Unknown""))"),22.39839376260022) -> 22.398394 | X9: =IFERROR(__xludf.DUMMYFUNCTION("IF(IMPORTRANGE(""https://docs.google.com/spreadsheets/d/10OcXjkVvXdQ20Dikey2wLwZD9Qs97Ke_ckzbHR2FA6E/edit?usp=sharing"", ""P1!$B$11"")=1, IFERROR(INDEX(IMPORTRANGE(""https://docs.google.com/spreadsheets/d/10OcXjkVvXdQ20Dikey2wLwZD9Qs97Ke_ckzbHR2FA6E/"&"edit?usp=sharing"", ""P1!$E$6:$BL$6""), MATCH(X3, IMPORTRANGE(""https://docs.google.com/spreadsheets/d/10OcXjkVvXdQ20Dikey2wLwZD9Qs97Ke_ckzbHR2FA6E/edit?usp=sharing"", ""P1!$E$4:$BL$4""), 0)), ""Unknown""), IF(IMPORTRANGE(""https://docs.google."&"com/spreadsheets/d/10OcXjkVvXdQ20Dikey2wLwZD9Qs97Ke_ckzbHR2FA6E/edit?usp=sharing"", ""P1!$B$11"")=2, 0, ""Unknown""))"),22.280995112288654) -> 22.280995 | Y9: =IFERROR(__xludf.DUMMYFUNCTION("IF(IMPORTRANGE(""https://docs.google.com/spreadsheets/d/10OcXjkVvXdQ20Dikey2wLwZD9Qs97Ke_ckzbHR2FA6E/edit?usp=sharing"", ""P1!$B$11"")=1, IFERROR(INDEX(IMPORTRANGE(""https://docs.google.com/spreadsheets/d/10OcXjkVvXdQ20Dikey2wLwZD9Qs97Ke_ckzbHR2FA6E/"&"edit?usp=sharing"", ""P1!$E$6:$BL$6""), MATCH(Y3, IMPORTRANGE(""https://docs.google.com/spreadsheets/d/10OcXjkVvXdQ20Dikey2wLwZD9Qs97Ke_ckzbHR2FA6E/edit?usp=sharing"", ""P1!$E$4:$BL$4""), 0)), ""Unknown""), IF(IMPORTRANGE(""https://docs.google."&"com/spreadsheets/d/10OcXjkVvXdQ20Dikey2wLwZD9Qs97Ke_ckzbHR2FA6E/edit?usp=sharing"", ""P1!$B$11"")=2, 0, ""Unknown""))"),22.16796942607327) -> 22.167969 | Z9: =IFERROR(__xludf.DUMMYFUNCTION("IF(IMPORTRANGE(""https://docs.google.com/spreadsheets/d/10OcXjkVvXdQ20Dikey2wLwZD9Qs97Ke_ckzbHR2FA6E/edit?usp=sharing"", ""P1!$B$11"")=1, IFERROR(INDEX(IMPORTRANGE(""https://docs.google.com/spreadsheets/d/10OcXjkVvXdQ20Dikey2wLwZD9Qs97Ke_ckzbHR2FA6E/"&"edit?usp=sharing"", ""P1!$E$6:$BL$6""), MATCH(Z3, IMPORTRANGE(""https://docs.google.com/spreadsheets/d/10OcXjkVvXdQ20Dikey2wLwZD9Qs97Ke_ckzbHR2FA6E/edit?usp=sharing"", ""P1!$E$4:$BL$4""), 0)), ""Unknown""), IF(IMPORTRANGE(""https://docs.google."&"com/spreadsheets/d/10OcXjkVvXdQ20Dikey2wLwZD9Qs97Ke_ckzbHR2FA6E/edit?usp=sharing"", ""P1!$B$11"")=2, 0, ""Unknown""))"),22.051778518888014) -> 22.051779 | AA9: =IFERROR(__xludf.DUMMYFUNCTION("IF(IMPORTRANGE(""https://docs.google.com/spreadsheets/d/10OcXjkVvXdQ20Dikey2wLwZD9Qs97Ke_ckzbHR2FA6E/edit?usp=sharing"", ""P1!$B$11"")=1, IFERROR(INDEX(IMPORTRANGE(""https://docs.google.com/spreadsheets/d/10OcXjkVvXdQ20Dikey2wLwZD9Qs97Ke_ckzbHR2FA6E/"&"edit?usp=sharing"", ""P1!$E$6:$BL$6""), MATCH(AA3, IMPORTRANGE(""https://docs.google.com/spreadsheets/d/10OcXjkVvXdQ20Dikey2wLwZD9Qs97Ke_ckzbHR2FA6E/edit?usp=sharing"", ""P1!$E$4:$BL$4""), 0)), ""Unknown""), IF(IMPORTRANGE(""https://docs.google"&".com/spreadsheets/d/10OcXjkVvXdQ20Dikey2wLwZD9Qs97Ke_ckzbHR2FA6E/edit?usp=sharing"", ""P1!$B$11"")=2, 0, ""Unknown""))"),21.93991558876276) -> 21.939916 | AB9: =IFERROR(__xludf.DUMMYFUNCTION("IF(IMPORTRANGE(""https://docs.google.com/spreadsheets/d/10OcXjkVvXdQ20Dikey2wLwZD9Qs97Ke_ckzbHR2FA6E/edit?usp=sharing"", ""P1!$B$11"")=1, IFERROR(INDEX(IMPORTRANGE(""https://docs.google.com/spreadsheets/d/10OcXjkVvXdQ20Dikey2wLwZD9Qs97Ke_ckzbHR2FA6E/"&"edit?usp=sharing"", ""P1!$E$6:$BL$6""), MATCH(AB3, IMPORTRANGE(""https://docs.google.com/spreadsheets/d/10OcXjkVvXdQ20Dikey2wLwZD9Qs97Ke_ckzbHR2FA6E/edit?usp=sharing"", ""P1!$E$4:$BL$4""), 0)), ""Unknown""), IF(IMPORTRANGE(""https://docs.google"&".com/spreadsheets/d/10OcXjkVvXdQ20Dikey2wLwZD9Qs97Ke_ckzbHR2FA6E/edit?usp=sharing"", ""P1!$B$11"")=2, 0, ""Unknown""))"),21.82492) -> 21.82492 | AC9: =IFERROR(__xludf.DUMMYFUNCTION("IF(IMPORTRANGE(""https://docs.google.com/spreadsheets/d/10OcXjkVvXdQ20Dikey2wLwZD9Qs97Ke_ckzbHR2FA6E/edit?usp=sharing"", ""P1!$B$11"")=1, IFERROR(INDEX(IMPORTRANGE(""https://docs.google.com/spreadsheets/d/10OcXjkVvXdQ20Dikey2wLwZD9Qs97Ke_ckzbHR2FA6E/"&"edit?usp=sharing"", ""P1!$E$6:$BL$6""), MATCH(AC3, IMPORTRANGE(""https://docs.google.com/spreadsheets/d/10OcXjkVvXdQ20Dikey2wLwZD9Qs97Ke_ckzbHR2FA6E/edit?usp=sharing"", ""P1!$E$4:$BL$4""), 0)), ""Unknown""), IF(IMPORTRANGE(""https://docs.google"&".com/spreadsheets/d/10OcXjkVvXdQ20Dikey2wLwZD9Qs97Ke_ckzbHR2FA6E/edit?usp=sharing"", ""P1!$B$11"")=2, 0, ""Unknown""))"),21.710527147623406) -> 21.710527 | AD9: =IFERROR(__xludf.DUMMYFUNCTION("IF(IMPORTRANGE(""https://docs.google.com/spreadsheets/d/10OcXjkVvXdQ20Dikey2wLwZD9Qs97Ke_ckzbHR2FA6E/edit?usp=sharing"", ""P1!$B$11"")=1, IFERROR(INDEX(IMPORTRANGE(""https://docs.google.com/spreadsheets/d/10OcXjkVvXdQ20Dikey2wLwZD9Qs97Ke_ckzbHR2FA6E/"&"edit?usp=sharing"", ""P1!$E$6:$BL$6""), MATCH(AD3, IMPORTRANGE(""https://docs.google.com/spreadsheets/d/10OcXjkVvXdQ20Dikey2wLwZD9Qs97Ke_ckzbHR2FA6E/edit?usp=sharing"", ""P1!$E$4:$BL$4""), 0)), ""Unknown""), IF(IMPORTRANGE(""https://docs.google"&".com/spreadsheets/d/10OcXjkVvXdQ20Dikey2wLwZD9Qs97Ke_ckzbHR2FA6E/edit?usp=sharing"", ""P1!$B$11"")=2, 0, ""Unknown""))"),21.607720007945925) -> 21.60772 | AE9: =IFERROR(__xludf.DUMMYFUNCTION("IF(IMPORTRANGE(""https://docs.google.com/spreadsheets/d/10OcXjkVvXdQ20Dikey2wLwZD9Qs97Ke_ckzbHR2FA6E/edit?usp=sharing"", ""P1!$B$11"")=1, IFERROR(INDEX(IMPORTRANGE(""https://docs.google.com/spreadsheets/d/10OcXjkVvXdQ20Dikey2wLwZD9Qs97Ke_ckzbHR2FA6E/"&"edit?usp=sharing"", ""P1!$E$6:$BL$6""), MATCH(AE3, IMPORTRANGE(""https://docs.google.com/spreadsheets/d/10OcXjkVvXdQ20Dikey2wLwZD9Qs97Ke_ckzbHR2FA6E/edit?usp=sharing"", ""P1!$E$4:$BL$4""), 0)), ""Unknown""), IF(IMPORTRANGE(""https://docs.google"&".com/spreadsheets/d/10OcXjkVvXdQ20Dikey2wLwZD9Qs97Ke_ckzbHR2FA6E/edit?usp=sharing"", ""P1!$B$11"")=2, 0, ""Unknown""))"),21.494465584788195) -> 21.494466 | AF9: =IFERROR(__xludf.DUMMYFUNCTION("IF(IMPORTRANGE(""https://docs.google.com/spreadsheets/d/10OcXjkVvXdQ20Dikey2wLwZD9Qs97Ke_ckzbHR2FA6E/edit?usp=sharing"", ""P1!$B$11"")=1, IFERROR(INDEX(IMPORTRANGE(""https://docs.google.com/spreadsheets/d/10OcXjkVvXdQ20Dikey2wLwZD9Qs97Ke_ckzbHR2FA6E/"&"edit?usp=sharing"", ""P1!$E$6:$BL$6""), MATCH(AF3, IMPORTRANGE(""https://docs.google.com/spreadsheets/d/10OcXjkVvXdQ20Dikey2wLwZD9Qs97Ke_ckzbHR2FA6E/edit?usp=sharing"", ""P1!$E$4:$BL$4""), 0)), ""Unknown""), IF(IMPORTRANGE(""https://docs.google"&".com/spreadsheets/d/10OcXjkVvXdQ20Dikey2wLwZD9Qs97Ke_ckzbHR2FA6E/edit?usp=sharing"", ""P1!$B$11"")=2, 0, ""Unknown""))"),21.385429758052886) -> 21.38543 | AG9: =IFERROR(__xludf.DUMMYFUNCTION("IF(IMPORTRANGE(""https://docs.google.com/spreadsheets/d/10OcXjkVvXdQ20Dikey2wLwZD9Qs97Ke_ckzbHR2FA6E/edit?usp=sharing"", ""P1!$B$11"")=1, IFERROR(INDEX(IMPORTRANGE(""https://docs.google.com/spreadsheets/d/10OcXjkVvXdQ20Dikey2wLwZD9Qs97Ke_ckzbHR2FA6E/"&"edit?usp=sharing"", ""P1!$E$6:$BL$6""), MATCH(AG3, IMPORTRANGE(""https://docs.google.com/spreadsheets/d/10OcXjkVvXdQ20Dikey2wLwZD9Qs97Ke_ckzbHR2FA6E/edit?usp=sharing"", ""P1!$E$4:$BL$4""), 0)), ""Unknown""), IF(IMPORTRANGE(""https://docs.google"&".com/spreadsheets/d/10OcXjkVvXdQ20Dikey2wLwZD9Qs97Ke_ckzbHR2FA6E/edit?usp=sharing"", ""P1!$B$11"")=2, 0, ""Unknown""))"),21.27334044412537) -> 21.27334 | AH9: =IFERROR(__xludf.DUMMYFUNCTION("IF(IMPORTRANGE(""https://docs.google.com/spreadsheets/d/10OcXjkVvXdQ20Dikey2wLwZD9Qs97Ke_ckzbHR2FA6E/edit?usp=sharing"", ""P1!$B$11"")=1, IFERROR(INDEX(IMPORTRANGE(""https://docs.google.com/spreadsheets/d/10OcXjkVvXdQ20Dikey2wLwZD9Qs97Ke_ckzbHR2FA6E/"&"edit?usp=sharing"", ""P1!$E$6:$BL$6""), MATCH(AH3, IMPORTRANGE(""https://docs.google.com/spreadsheets/d/10OcXjkVvXdQ20Dikey2wLwZD9Qs97Ke_ckzbHR2FA6E/edit?usp=sharing"", ""P1!$E$4:$BL$4""), 0)), ""Unknown""), IF(IMPORTRANGE(""https://docs.google"&".com/spreadsheets/d/10OcXjkVvXdQ20Dikey2wLwZD9Qs97Ke_ckzbHR2FA6E/edit?usp=sharing"", ""P1!$B$11"")=2, 0, ""Unknown""))"),21.16542632764748) -> 21.165426 | AI9: =IFERROR(__xludf.DUMMYFUNCTION("IF(IMPORTRANGE(""https://docs.google.com/spreadsheets/d/10OcXjkVvXdQ20Dikey2wLwZD9Qs97Ke_ckzbHR2FA6E/edit?usp=sharing"", ""P1!$B$11"")=1, IFERROR(INDEX(IMPORTRANGE(""https://docs.google.com/spreadsheets/d/10OcXjkVvXdQ20Dikey2wLwZD9Qs97Ke_ckzbHR2FA6E/"&"edit?usp=sharing"", ""P1!$E$6:$BL$6""), MATCH(AI3, IMPORTRANGE(""https://docs.google.com/spreadsheets/d/10OcXjkVvXdQ20Dikey2wLwZD9Qs97Ke_ckzbHR2FA6E/edit?usp=sharing"", ""P1!$E$4:$BL$4""), 0)), ""Unknown""), IF(IMPORTRANGE(""https://docs.google"&".com/spreadsheets/d/10OcXjkVvXdQ20Dikey2wLwZD9Qs97Ke_ckzbHR2FA6E/edit?usp=sharing"", ""P1!$B$11"")=2, 0, ""Unknown""))"),21.054490136844205) -> 21.05449 | AJ9: =IFERROR(__xludf.DUMMYFUNCTION("IF(IMPORTRANGE(""https://docs.google.com/spreadsheets/d/10OcXjkVvXdQ20Dikey2wLwZD9Qs97Ke_ckzbHR2FA6E/edit?usp=sharing"", ""P1!$B$11"")=1, IFERROR(INDEX(IMPORTRANGE(""https://docs.google.com/spreadsheets/d/10OcXjkVvXdQ20Dikey2wLwZD9Qs97Ke_ckzbHR2FA6E/"&"edit?usp=sharing"", ""P1!$E$6:$BL$6""), MATCH(AJ3, IMPORTRANGE(""https://docs.google.com/spreadsheets/d/10OcXjkVvXdQ20Dikey2wLwZD9Qs97Ke_ckzbHR2FA6E/edit?usp=sharing"", ""P1!$E$4:$BL$4""), 0)), ""Unknown""), IF(IMPORTRANGE(""https://docs.google"&".com/spreadsheets/d/10OcXjkVvXdQ20Dikey2wLwZD9Qs97Ke_ckzbHR2FA6E/edit?usp=sharing"", ""P1!$B$11"")=2, 0, ""Unknown""))"),20.944135405551336) -> 20.944135 | AK9: =IFERROR(__xludf.DUMMYFUNCTION("IF(IMPORTRANGE(""https://docs.google.com/spreadsheets/d/10OcXjkVvXdQ20Dikey2wLwZD9Qs97Ke_ckzbHR2FA6E/edit?usp=sharing"", ""P1!$B$11"")=1, IFERROR(INDEX(IMPORTRANGE(""https://docs.google.com/spreadsheets/d/10OcXjkVvXdQ20Dikey2wLwZD9Qs97Ke_ckzbHR2FA6E/"&"edit?usp=sharing"", ""P1!$E$6:$BL$6""), MATCH(AK3, IMPORTRANGE(""https://docs.google.com/spreadsheets/d/10OcXjkVvXdQ20Dikey2wLwZD9Qs97Ke_ckzbHR2FA6E/edit?usp=sharing"", ""P1!$E$4:$BL$4""), 0)), ""Unknown""), IF(IMPORTRANGE(""https://docs.google"&".com/spreadsheets/d/10OcXjkVvXdQ20Dikey2wLwZD9Qs97Ke_ckzbHR2FA6E/edit?usp=sharing"", ""P1!$B$11"")=2, 0, ""Unknown""))"),20.837891260508872) -> 20.837891 | AL9: =IFERROR(__xludf.DUMMYFUNCTION("IF(IMPORTRANGE(""https://docs.google.com/spreadsheets/d/10OcXjkVvXdQ20Dikey2wLwZD9Qs97Ke_ckzbHR2FA6E/edit?usp=sharing"", ""P1!$B$11"")=1, IFERROR(INDEX(IMPORTRANGE(""https://docs.google.com/spreadsheets/d/10OcXjkVvXdQ20Dikey2wLwZD9Qs97Ke_ckzbHR2FA6E/"&"edit?usp=sharing"", ""P1!$E$6:$BL$6""), MATCH(AL3, IMPORTRANGE(""https://docs.google.com/spreadsheets/d/10OcXjkVvXdQ20Dikey2wLwZD9Qs97Ke_ckzbHR2FA6E/edit?usp=sharing"", ""P1!$E$4:$BL$4""), 0)), ""Unknown""), IF(IMPORTRANGE(""https://docs.google"&".com/spreadsheets/d/10OcXjkVvXdQ20Dikey2wLwZD9Qs97Ke_ckzbHR2FA6E/edit?usp=sharing"", ""P1!$B$11"")=2, 0, ""Unknown""))"),20.728671807754733) -> 20.728672 | AM9: =IFERROR(__xludf.DUMMYFUNCTION("IF(IMPORTRANGE(""https://docs.google.com/spreadsheets/d/10OcXjkVvXdQ20Dikey2wLwZD9Qs97Ke_ckzbHR2FA6E/edit?usp=sharing"", ""P1!$B$11"")=1, IFERROR(INDEX(IMPORTRANGE(""https://docs.google.com/spreadsheets/d/10OcXjkVvXdQ20Dikey2wLwZD9Qs97Ke_ckzbHR2FA6E/"&"edit?usp=sharing"", ""P1!$E$6:$BL$6""), MATCH(AM3, IMPORTRANGE(""https://docs.google.com/spreadsheets/d/10OcXjkVvXdQ20Dikey2wLwZD9Qs97Ke_ckzbHR2FA6E/edit?usp=sharing"", ""P1!$E$4:$BL$4""), 0)), ""Unknown""), IF(IMPORTRANGE(""https://docs.google"&".com/spreadsheets/d/10OcXjkVvXdQ20Dikey2wLwZD9Qs97Ke_ckzbHR2FA6E/edit?usp=sharing"", ""P1!$B$11"")=2, 0, ""Unknown""))"),20.623520653436994) -> 20.623521 | AN9: =IFERROR(__xludf.DUMMYFUNCTION("IF(IMPORTRANGE(""https://docs.google.com/spreadsheets/d/10OcXjkVvXdQ20Dikey2wLwZD9Qs97Ke_ckzbHR2FA6E/edit?usp=sharing"", ""P1!$B$11"")=1, IFERROR(INDEX(IMPORTRANGE(""https://docs.google.com/spreadsheets/d/10OcXjkVvXdQ20Dikey2wLwZD9Qs97Ke_ckzbHR2FA6E/"&"edit?usp=sharing"", ""P1!$E$6:$BL$6""), MATCH(AN3, IMPORTRANGE(""https://docs.google.com/spreadsheets/d/10OcXjkVvXdQ20Dikey2wLwZD9Qs97Ke_ckzbHR2FA6E/edit?usp=sharing"", ""P1!$E$4:$BL$4""), 0)), ""Unknown""), IF(IMPORTRANGE(""https://docs.google"&".com/spreadsheets/d/10OcXjkVvXdQ20Dikey2wLwZD9Qs97Ke_ckzbHR2FA6E/edit?usp=sharing"", ""P1!$B$11"")=2, 0, ""Unknown""))"),20.515424799999998) -> 20.515425 | AO9: =IFERROR(__xludf.DUMMYFUNCTION("IF(IMPORTRANGE(""https://docs.google.com/spreadsheets/d/10OcXjkVvXdQ20Dikey2wLwZD9Qs97Ke_ckzbHR2FA6E/edit?usp=sharing"", ""P1!$B$11"")=1, IFERROR(INDEX(IMPORTRANGE(""https://docs.google.com/spreadsheets/d/10OcXjkVvXdQ20Dikey2wLwZD9Qs97Ke_ckzbHR2FA6E/"&"edit?usp=sharing"", ""P1!$E$6:$BL$6""), MATCH(AO3, IMPORTRANGE(""https://docs.google.com/spreadsheets/d/10OcXjkVvXdQ20Dikey2wLwZD9Qs97Ke_ckzbHR2FA6E/edit?usp=sharing"", ""P1!$E$4:$BL$4""), 0)), ""Unknown""), IF(IMPORTRANGE(""https://docs.google"&".com/spreadsheets/d/10OcXjkVvXdQ20Dikey2wLwZD9Qs97Ke_ckzbHR2FA6E/edit?usp=sharing"", ""P1!$B$11"")=2, 0, ""Unknown""))"),20.407895518766) -> 20.407896 | AP9: =IFERROR(__xludf.DUMMYFUNCTION("IF(IMPORTRANGE(""https://docs.google.com/spreadsheets/d/10OcXjkVvXdQ20Dikey2wLwZD9Qs97Ke_ckzbHR2FA6E/edit?usp=sharing"", ""P1!$B$11"")=1, IFERROR(INDEX(IMPORTRANGE(""https://docs.google.com/spreadsheets/d/10OcXjkVvXdQ20Dikey2wLwZD9Qs97Ke_ckzbHR2FA6E/"&"edit?usp=sharing"", ""P1!$E$6:$BL$6""), MATCH(AP3, IMPORTRANGE(""https://docs.google.com/spreadsheets/d/10OcXjkVvXdQ20Dikey2wLwZD9Qs97Ke_ckzbHR2FA6E/edit?usp=sharing"", ""P1!$E$4:$BL$4""), 0)), ""Unknown""), IF(IMPORTRANGE(""https://docs.google"&".com/spreadsheets/d/10OcXjkVvXdQ20Dikey2wLwZD9Qs97Ke_ckzbHR2FA6E/edit?usp=sharing"", ""P1!$B$11"")=2, 0, ""Unknown""))"),20.307813901451702) -> 20.307814 | AQ9: =IFERROR(__xludf.DUMMYFUNCTION("IF(IMPORTRANGE(""https://docs.google.com/spreadsheets/d/10OcXjkVvXdQ20Dikey2wLwZD9Qs97Ke_ckzbHR2FA6E/edit?usp=sharing"", ""P1!$B$11"")=1, IFERROR(INDEX(IMPORTRANGE(""https://docs.google.com/spreadsheets/d/10OcXjkVvXdQ20Dikey2wLwZD9Qs97Ke_ckzbHR2FA6E/"&"edit?usp=sharing"", ""P1!$E$6:$BL$6""), MATCH(AQ3, IMPORTRANGE(""https://docs.google.com/spreadsheets/d/10OcXjkVvXdQ20Dikey2wLwZD9Qs97Ke_ckzbHR2FA6E/edit?usp=sharing"", ""P1!$E$4:$BL$4""), 0)), ""Unknown""), IF(IMPORTRANGE(""https://docs.google"&".com/spreadsheets/d/10OcXjkVvXdQ20Dikey2wLwZD9Qs97Ke_ckzbHR2FA6E/edit?usp=sharing"", ""P1!$B$11"")=2, 0, ""Unknown""))"),20.201372789286342) -> 20.201373 | AR9: =IFERROR(__xludf.DUMMYFUNCTION("IF(IMPORTRANGE(""https://docs.google.com/spreadsheets/d/10OcXjkVvXdQ20Dikey2wLwZD9Qs97Ke_ckzbHR2FA6E/edit?usp=sharing"", ""P1!$B$11"")=1, IFERROR(INDEX(IMPORTRANGE(""https://docs.google.com/spreadsheets/d/10OcXjkVvXdQ20Dikey2wLwZD9Qs97Ke_ckzbHR2FA6E/"&"edit?usp=sharing"", ""P1!$E$6:$BL$6""), MATCH(AR3, IMPORTRANGE(""https://docs.google.com/spreadsheets/d/10OcXjkVvXdQ20Dikey2wLwZD9Qs97Ke_ckzbHR2FA6E/edit?usp=sharing"", ""P1!$E$4:$BL$4""), 0)), ""Unknown""), IF(IMPORTRANGE(""https://docs.google"&".com/spreadsheets/d/10OcXjkVvXdQ20Dikey2wLwZD9Qs97Ke_ckzbHR2FA6E/edit?usp=sharing"", ""P1!$B$11"")=2, 0, ""Unknown""))"),20.098896485580198) -> 20.098896 | AS9: =IFERROR(__xludf.DUMMYFUNCTION("IF(IMPORTRANGE(""https://docs.google.com/spreadsheets/d/10OcXjkVvXdQ20Dikey2wLwZD9Qs97Ke_ckzbHR2FA6E/edit?usp=sharing"", ""P1!$B$11"")=1, IFERROR(INDEX(IMPORTRANGE(""https://docs.google.com/spreadsheets/d/10OcXjkVvXdQ20Dikey2wLwZD9Qs97Ke_ckzbHR2FA6E/"&"edit?usp=sharing"", ""P1!$E$6:$BL$6""), MATCH(AS3, IMPORTRANGE(""https://docs.google.com/spreadsheets/d/10OcXjkVvXdQ20Dikey2wLwZD9Qs97Ke_ckzbHR2FA6E/edit?usp=sharing"", ""P1!$E$4:$BL$4""), 0)), ""Unknown""), IF(IMPORTRANGE(""https://docs.google"&".com/spreadsheets/d/10OcXjkVvXdQ20Dikey2wLwZD9Qs97Ke_ckzbHR2FA6E/edit?usp=sharing"", ""P1!$B$11"")=2, 0, ""Unknown""))"),19.993550390446412) -> 19.99355 | AT9: =IFERROR(__xludf.DUMMYFUNCTION("IF(IMPORTRANGE(""https://docs.google.com/spreadsheets/d/10OcXjkVvXdQ20Dikey2wLwZD9Qs97Ke_ckzbHR2FA6E/edit?usp=sharing"", ""P1!$B$11"")=1, IFERROR(INDEX(IMPORTRANGE(""https://docs.google.com/spreadsheets/d/10OcXjkVvXdQ20Dikey2wLwZD9Qs97Ke_ckzbHR2FA6E/"&"edit?usp=sharing"", ""P1!$E$6:$BL$6""), MATCH(AT3, IMPORTRANGE(""https://docs.google.com/spreadsheets/d/10OcXjkVvXdQ20Dikey2wLwZD9Qs97Ke_ckzbHR2FA6E/edit?usp=sharing"", ""P1!$E$4:$BL$4""), 0)), ""Unknown""), IF(IMPORTRANGE(""https://docs.google"&".com/spreadsheets/d/10OcXjkVvXdQ20Dikey2wLwZD9Qs97Ke_ckzbHR2FA6E/edit?usp=sharing"", ""P1!$B$11"")=2, 0, ""Unknown""))"),19.89212831565246) -> 19.892128 | AU9: =IFERROR(__xludf.DUMMYFUNCTION("IF(IMPORTRANGE(""https://docs.google.com/spreadsheets/d/10OcXjkVvXdQ20Dikey2wLwZD9Qs97Ke_ckzbHR2FA6E/edit?usp=sharing"", ""P1!$B$11"")=1, IFERROR(INDEX(IMPORTRANGE(""https://docs.google.com/spreadsheets/d/10OcXjkVvXdQ20Dikey2wLwZD9Qs97Ke_ckzbHR2FA6E/"&"edit?usp=sharing"", ""P1!$E$6:$BL$6""), MATCH(AU3, IMPORTRANGE(""https://docs.google.com/spreadsheets/d/10OcXjkVvXdQ20Dikey2wLwZD9Qs97Ke_ckzbHR2FA6E/edit?usp=sharing"", ""P1!$E$4:$BL$4""), 0)), ""Unknown""), IF(IMPORTRANGE(""https://docs.google"&".com/spreadsheets/d/10OcXjkVvXdQ20Dikey2wLwZD9Qs97Ke_ckzbHR2FA6E/edit?usp=sharing"", ""P1!$B$11"")=2, 0, ""Unknown""))"),19.787865972520454) -> 19.787866 | AV9: =IFERROR(__xludf.DUMMYFUNCTION("IF(IMPORTRANGE(""https://docs.google.com/spreadsheets/d/10OcXjkVvXdQ20Dikey2wLwZD9Qs97Ke_ckzbHR2FA6E/edit?usp=sharing"", ""P1!$B$11"")=1, IFERROR(INDEX(IMPORTRANGE(""https://docs.google.com/spreadsheets/d/10OcXjkVvXdQ20Dikey2wLwZD9Qs97Ke_ckzbHR2FA6E/"&"edit?usp=sharing"", ""P1!$E$6:$BL$6""), MATCH(AV3, IMPORTRANGE(""https://docs.google.com/spreadsheets/d/10OcXjkVvXdQ20Dikey2wLwZD9Qs97Ke_ckzbHR2FA6E/edit?usp=sharing"", ""P1!$E$4:$BL$4""), 0)), ""Unknown""), IF(IMPORTRANGE(""https://docs.google"&".com/spreadsheets/d/10OcXjkVvXdQ20Dikey2wLwZD9Qs97Ke_ckzbHR2FA6E/edit?usp=sharing"", ""P1!$B$11"")=2, 0, ""Unknown""))"),19.6841501086803) -> 19.68415 | AW9: =IFERROR(__xludf.DUMMYFUNCTION("IF(IMPORTRANGE(""https://docs.google.com/spreadsheets/d/10OcXjkVvXdQ20Dikey2wLwZD9Qs97Ke_ckzbHR2FA6E/edit?usp=sharing"", ""P1!$B$11"")=1, IFERROR(INDEX(IMPORTRANGE(""https://docs.google.com/spreadsheets/d/10OcXjkVvXdQ20Dikey2wLwZD9Qs97Ke_ckzbHR2FA6E/"&"edit?usp=sharing"", ""P1!$E$6:$BL$6""), MATCH(AW3, IMPORTRANGE(""https://docs.google.com/spreadsheets/d/10OcXjkVvXdQ20Dikey2wLwZD9Qs97Ke_ckzbHR2FA6E/edit?usp=sharing"", ""P1!$E$4:$BL$4""), 0)), ""Unknown""), IF(IMPORTRANGE(""https://docs.google"&".com/spreadsheets/d/10OcXjkVvXdQ20Dikey2wLwZD9Qs97Ke_ckzbHR2FA6E/edit?usp=sharing"", ""P1!$B$11"")=2, 0, ""Unknown""))"),19.584297540947667) -> 19.584298 | AX9: =IFERROR(__xludf.DUMMYFUNCTION("IF(IMPORTRANGE(""https://docs.google.com/spreadsheets/d/10OcXjkVvXdQ20Dikey2wLwZD9Qs97Ke_ckzbHR2FA6E/edit?usp=sharing"", ""P1!$B$11"")=1, IFERROR(INDEX(IMPORTRANGE(""https://docs.google.com/spreadsheets/d/10OcXjkVvXdQ20Dikey2wLwZD9Qs97Ke_ckzbHR2FA6E/"&"edit?usp=sharing"", ""P1!$E$6:$BL$6""), MATCH(AX3, IMPORTRANGE(""https://docs.google.com/spreadsheets/d/10OcXjkVvXdQ20Dikey2wLwZD9Qs97Ke_ckzbHR2FA6E/edit?usp=sharing"", ""P1!$E$4:$BL$4""), 0)), ""Unknown""), IF(IMPORTRANGE(""https://docs.google"&".com/spreadsheets/d/10OcXjkVvXdQ20Dikey2wLwZD9Qs97Ke_ckzbHR2FA6E/edit?usp=sharing"", ""P1!$B$11"")=2, 0, ""Unknown""))"),19.48164865804221) -> 19.481649 | AY9: =IFERROR(__xludf.DUMMYFUNCTION("IF(IMPORTRANGE(""https://docs.google.com/spreadsheets/d/10OcXjkVvXdQ20Dikey2wLwZD9Qs97Ke_ckzbHR2FA6E/edit?usp=sharing"", ""P1!$B$11"")=1, IFERROR(INDEX(IMPORTRANGE(""https://docs.google.com/spreadsheets/d/10OcXjkVvXdQ20Dikey2wLwZD9Qs97Ke_ckzbHR2FA6E/"&"edit?usp=sharing"", ""P1!$E$6:$BL$6""), MATCH(AY3, IMPORTRANGE(""https://docs.google.com/spreadsheets/d/10OcXjkVvXdQ20Dikey2wLwZD9Qs97Ke_ckzbHR2FA6E/edit?usp=sharing"", ""P1!$E$4:$BL$4""), 0)), ""Unknown""), IF(IMPORTRANGE(""https://docs.google"&".com/spreadsheets/d/10OcXjkVvXdQ20Dikey2wLwZD9Qs97Ke_ckzbHR2FA6E/edit?usp=sharing"", ""P1!$B$11"")=2, 0, ""Unknown""))"),19.38282332743712) -> 19.382823 | AZ9: =IFERROR(__xludf.DUMMYFUNCTION("IF(IMPORTRANGE(""https://docs.google.com/spreadsheets/d/10OcXjkVvXdQ20Dikey2wLwZD9Qs97Ke_ckzbHR2FA6E/edit?usp=sharing"", ""P1!$B$11"")=1, IFERROR(INDEX(IMPORTRANGE(""https://docs.google.com/spreadsheets/d/10OcXjkVvXdQ20Dikey2wLwZD9Qs97Ke_ckzbHR2FA6E/"&"edit?usp=sharing"", ""P1!$E$6:$BL$6""), MATCH(AZ3, IMPORTRANGE(""https://docs.google.com/spreadsheets/d/10OcXjkVvXdQ20Dikey2wLwZD9Qs97Ke_ckzbHR2FA6E/edit?usp=sharing"", ""P1!$E$4:$BL$4""), 0)), ""Unknown""), IF(IMPORTRANGE(""https://docs.google"&".com/spreadsheets/d/10OcXjkVvXdQ20Dikey2wLwZD9Qs97Ke_ckzbHR2FA6E/edit?usp=sharing"", ""P1!$B$11"")=2, 0, ""Unknown""))"),19.281230448859006) -> 19.28123 | BA9: =IFERROR(__xludf.DUMMYFUNCTION("IF(IMPORTRANGE(""https://docs.google.com/spreadsheets/d/10OcXjkVvXdQ20Dikey2wLwZD9Qs97Ke_ckzbHR2FA6E/edit?usp=sharing"", ""P1!$B$11"")=1, IFERROR(INDEX(IMPORTRANGE(""https://docs.google.com/spreadsheets/d/10OcXjkVvXdQ20Dikey2wLwZD9Qs97Ke_ckzbHR2FA6E/"&"edit?usp=sharing"", ""P1!$E$6:$BL$6""), MATCH(BA3, IMPORTRANGE(""https://docs.google.com/spreadsheets/d/10OcXjkVvXdQ20Dikey2wLwZD9Qs97Ke_ckzbHR2FA6E/edit?usp=sharing"", ""P1!$E$4:$BL$4""), 0)), ""Unknown""), IF(IMPORTRANGE(""https://docs.google"&".com/spreadsheets/d/10OcXjkVvXdQ20Dikey2wLwZD9Qs97Ke_ckzbHR2FA6E/edit?usp=sharing"", ""P1!$B$11"")=2, 0, ""Unknown""))"),19.180170057875884) -> 19.18017 | BB9: =IFERROR(__xludf.DUMMYFUNCTION("IF(IMPORTRANGE(""https://docs.google.com/spreadsheets/d/10OcXjkVvXdQ20Dikey2wLwZD9Qs97Ke_ckzbHR2FA6E/edit?usp=sharing"", ""P1!$B$11"")=1, IFERROR(INDEX(IMPORTRANGE(""https://docs.google.com/spreadsheets/d/10OcXjkVvXdQ20Dikey2wLwZD9Qs97Ke_ckzbHR2FA6E/"&"edit?usp=sharing"", ""P1!$E$6:$BL$6""), MATCH(BB3, IMPORTRANGE(""https://docs.google.com/spreadsheets/d/10OcXjkVvXdQ20Dikey2wLwZD9Qs97Ke_ckzbHR2FA6E/edit?usp=sharing"", ""P1!$E$4:$BL$4""), 0)), ""Unknown""), IF(IMPORTRANGE(""https://docs.google"&".com/spreadsheets/d/10OcXjkVvXdQ20Dikey2wLwZD9Qs97Ke_ckzbHR2FA6E/edit?usp=sharing"", ""P1!$B$11"")=2, 0, ""Unknown""))"),19.0893450673646) -> 19.089345 | BC9: =IFERROR(__xludf.DUMMYFUNCTION("IF(IMPORTRANGE(""https://docs.google.com/spreadsheets/d/10OcXjkVvXdQ20Dikey2wLwZD9Qs97Ke_ckzbHR2FA6E/edit?usp=sharing"", ""P1!$B$11"")=1, IFERROR(INDEX(IMPORTRANGE(""https://docs.google.com/spreadsheets/d/10OcXjkVvXdQ20Dikey2wLwZD9Qs97Ke_ckzbHR2FA6E/"&"edit?usp=sharing"", ""P1!$E$6:$BL$6""), MATCH(BC3, IMPORTRANGE(""https://docs.google.com/spreadsheets/d/10OcXjkVvXdQ20Dikey2wLwZD9Qs97Ke_ckzbHR2FA6E/edit?usp=sharing"", ""P1!$E$4:$BL$4""), 0)), ""Unknown""), IF(IMPORTRANGE(""https://docs.google"&".com/spreadsheets/d/10OcXjkVvXdQ20Dikey2wLwZD9Qs97Ke_ckzbHR2FA6E/edit?usp=sharing"", ""P1!$B$11"")=2, 0, ""Unknown""))"),18.98929042192916) -> 18.98929 | BD9: =IFERROR(__xludf.DUMMYFUNCTION("IF(IMPORTRANGE(""https://docs.google.com/spreadsheets/d/10OcXjkVvXdQ20Dikey2wLwZD9Qs97Ke_ckzbHR2FA6E/edit?usp=sharing"", ""P1!$B$11"")=1, IFERROR(INDEX(IMPORTRANGE(""https://docs.google.com/spreadsheets/d/10OcXjkVvXdQ20Dikey2wLwZD9Qs97Ke_ckzbHR2FA6E/"&"edit?usp=sharing"", ""P1!$E$6:$BL$6""), MATCH(BD3, IMPORTRANGE(""https://docs.google.com/spreadsheets/d/10OcXjkVvXdQ20Dikey2wLwZD9Qs97Ke_ckzbHR2FA6E/edit?usp=sharing"", ""P1!$E$4:$BL$4""), 0)), ""Unknown""), IF(IMPORTRANGE(""https://docs.google"&".com/spreadsheets/d/10OcXjkVvXdQ20Dikey2wLwZD9Qs97Ke_ckzbHR2FA6E/edit?usp=sharing"", ""P1!$B$11"")=2, 0, ""Unknown""))"),18.89296269644539) -> 18.892963 | BE9: =IFERROR(__xludf.DUMMYFUNCTION("IF(IMPORTRANGE(""https://docs.google.com/spreadsheets/d/10OcXjkVvXdQ20Dikey2wLwZD9Qs97Ke_ckzbHR2FA6E/edit?usp=sharing"", ""P1!$B$11"")=1, IFERROR(INDEX(IMPORTRANGE(""https://docs.google.com/spreadsheets/d/10OcXjkVvXdQ20Dikey2wLwZD9Qs97Ke_ckzbHR2FA6E/"&"edit?usp=sharing"", ""P1!$E$6:$BL$6""), MATCH(BE3, IMPORTRANGE(""https://docs.google.com/spreadsheets/d/10OcXjkVvXdQ20Dikey2wLwZD9Qs97Ke_ckzbHR2FA6E/edit?usp=sharing"", ""P1!$E$4:$BL$4""), 0)), ""Unknown""), IF(IMPORTRANGE(""https://docs.google"&".com/spreadsheets/d/10OcXjkVvXdQ20Dikey2wLwZD9Qs97Ke_ckzbHR2FA6E/edit?usp=sharing"", ""P1!$B$11"")=2, 0, ""Unknown""))"),18.793937367019627) -> 18.793937 | BF9: =IFERROR(__xludf.DUMMYFUNCTION("IF(IMPORTRANGE(""https://docs.google.com/spreadsheets/d/10OcXjkVvXdQ20Dikey2wLwZD9Qs97Ke_ckzbHR2FA6E/edit?usp=sharing"", ""P1!$B$11"")=1, IFERROR(INDEX(IMPORTRANGE(""https://docs.google.com/spreadsheets/d/10OcXjkVvXdQ20Dikey2wLwZD9Qs97Ke_ckzbHR2FA6E/"&"edit?usp=sharing"", ""P1!$E$6:$BL$6""), MATCH(BF3, IMPORTRANGE(""https://docs.google.com/spreadsheets/d/10OcXjkVvXdQ20Dikey2wLwZD9Qs97Ke_ckzbHR2FA6E/edit?usp=sharing"", ""P1!$E$4:$BL$4""), 0)), ""Unknown""), IF(IMPORTRANGE(""https://docs.google"&".com/spreadsheets/d/10OcXjkVvXdQ20Dikey2wLwZD9Qs97Ke_ckzbHR2FA6E/edit?usp=sharing"", ""P1!$B$11"")=2, 0, ""Unknown""))"),18.69860061671331) -> 18.698601 | BG9: =IFERROR(__xludf.DUMMYFUNCTION("IF(IMPORTRANGE(""https://docs.google.com/spreadsheets/d/10OcXjkVvXdQ20Dikey2wLwZD9Qs97Ke_ckzbHR2FA6E/edit?usp=sharing"", ""P1!$B$11"")=1, IFERROR(INDEX(IMPORTRANGE(""https://docs.google.com/spreadsheets/d/10OcXjkVvXdQ20Dikey2wLwZD9Qs97Ke_ckzbHR2FA6E/"&"edit?usp=sharing"", ""P1!$E$6:$BL$6""), MATCH(BG3, IMPORTRANGE(""https://docs.google.com/spreadsheets/d/10OcXjkVvXdQ20Dikey2wLwZD9Qs97Ke_ckzbHR2FA6E/edit?usp=sharing"", ""P1!$E$4:$BL$4""), 0)), ""Unknown""), IF(IMPORTRANGE(""https://docs.google"&".com/spreadsheets/d/10OcXjkVvXdQ20Dikey2wLwZD9Qs97Ke_ckzbHR2FA6E/edit?usp=sharing"", ""P1!$B$11"")=2, 0, ""Unknown""))"),18.600594014169225) -> 18.600594 | BH9: =IFERROR(__xludf.DUMMYFUNCTION("IF(IMPORTRANGE(""https://docs.google.com/spreadsheets/d/10OcXjkVvXdQ20Dikey2wLwZD9Qs97Ke_ckzbHR2FA6E/edit?usp=sharing"", ""P1!$B$11"")=1, IFERROR(INDEX(IMPORTRANGE(""https://docs.google.com/spreadsheets/d/10OcXjkVvXdQ20Dikey2wLwZD9Qs97Ke_ckzbHR2FA6E/"&"edit?usp=sharing"", ""P1!$E$6:$BL$6""), MATCH(BH3, IMPORTRANGE(""https://docs.google.com/spreadsheets/d/10OcXjkVvXdQ20Dikey2wLwZD9Qs97Ke_ckzbHR2FA6E/edit?usp=sharing"", ""P1!$E$4:$BL$4""), 0)), ""Unknown""), IF(IMPORTRANGE(""https://docs.google"&".com/spreadsheets/d/10OcXjkVvXdQ20Dikey2wLwZD9Qs97Ke_ckzbHR2FA6E/edit?usp=sharing"", ""P1!$B$11"")=2, 0, ""Unknown""))"),18.503101102159476) -> 18.503101 | BI9: =IFERROR(__xludf.DUMMYFUNCTION("IF(IMPORTRANGE(""https://docs.google.com/spreadsheets/d/10OcXjkVvXdQ20Dikey2wLwZD9Qs97Ke_ckzbHR2FA6E/edit?usp=sharing"", ""P1!$B$11"")=1, IFERROR(INDEX(IMPORTRANGE(""https://docs.google.com/spreadsheets/d/10OcXjkVvXdQ20Dikey2wLwZD9Qs97Ke_ckzbHR2FA6E/"&"edit?usp=sharing"", ""P1!$E$6:$BL$6""), MATCH(BI3, IMPORTRANGE(""https://docs.google.com/spreadsheets/d/10OcXjkVvXdQ20Dikey2wLwZD9Qs97Ke_ckzbHR2FA6E/edit?usp=sharing"", ""P1!$E$4:$BL$4""), 0)), ""Unknown""), IF(IMPORTRANGE(""https://docs.google"&".com/spreadsheets/d/10OcXjkVvXdQ20Dikey2wLwZD9Qs97Ke_ckzbHR2FA6E/edit?usp=sharing"", ""P1!$B$11"")=2, 0, ""Unknown""))"),18.409239688490803) -> 18.40924 | BJ9: =IFERROR(__xludf.DUMMYFUNCTION("IF(IMPORTRANGE(""https://docs.google.com/spreadsheets/d/10OcXjkVvXdQ20Dikey2wLwZD9Qs97Ke_ckzbHR2FA6E/edit?usp=sharing"", ""P1!$B$11"")=1, IFERROR(INDEX(IMPORTRANGE(""https://docs.google.com/spreadsheets/d/10OcXjkVvXdQ20Dikey2wLwZD9Qs97Ke_ckzbHR2FA6E/"&"edit?usp=sharing"", ""P1!$E$6:$BL$6""), MATCH(BJ3, IMPORTRANGE(""https://docs.google.com/spreadsheets/d/10OcXjkVvXdQ20Dikey2wLwZD9Qs97Ke_ckzbHR2FA6E/edit?usp=sharing"", ""P1!$E$4:$BL$4""), 0)), ""Unknown""), IF(IMPORTRANGE(""https://docs.google"&".com/spreadsheets/d/10OcXjkVvXdQ20Dikey2wLwZD9Qs97Ke_ckzbHR2FA6E/edit?usp=sharing"", ""P1!$B$11"")=2, 0, ""Unknown""))"),18.312749738559678) -> 18.31275 | BK9: =IFERROR(__xludf.DUMMYFUNCTION("IF(IMPORTRANGE(""https://docs.google.com/spreadsheets/d/10OcXjkVvXdQ20Dikey2wLwZD9Qs97Ke_ckzbHR2FA6E/edit?usp=sharing"", ""P1!$B$11"")=1, IFERROR(INDEX(IMPORTRANGE(""https://docs.google.com/spreadsheets/d/10OcXjkVvXdQ20Dikey2wLwZD9Qs97Ke_ckzbHR2FA6E/"&"edit?usp=sharing"", ""P1!$E$6:$BL$6""), MATCH(BK3, IMPORTRANGE(""https://docs.google.com/spreadsheets/d/10OcXjkVvXdQ20Dikey2wLwZD9Qs97Ke_ckzbHR2FA6E/edit?usp=sharing"", ""P1!$E$4:$BL$4""), 0)), ""Unknown""), IF(IMPORTRANGE(""https://docs.google"&".com/spreadsheets/d/10OcXjkVvXdQ20Dikey2wLwZD9Qs97Ke_ckzbHR2FA6E/edit?usp=sharing"", ""P1!$B$11"")=2, 0, ""Unknown""))"),18.219853927790894) -> 18.219854 | BL9: =AVERAGE(D9:BK9) -> 21.301016
